
🚀 开始测试Queue时间戳修复
时间: 2025-07-29 21:17:01.024700
服务器: http://localhost:30000

============================================================
测试单个请求的Queue时间戳
============================================================

Traceback (most recent call last):
  File "/usr/local/conda/envs/lg/lib/python3.10/site-packages/aiohttp/connector.py", line 1268, in _wrap_create_connection
    sock = await aiohappyeyeballs.start_connection(
  File "/usr/local/conda/envs/lg/lib/python3.10/site-packages/aiohappyeyeballs/impl.py", line 141, in start_connection
    raise OSError(first_errno, msg)
ConnectionRefusedError: [Errno 111] Multiple exceptions: [Errno 111] Connect call failed ('::1', 30000, 0, 0), [Errno 111] Connect call failed ('127.0.0.1', 30000)

The above exception was the direct cause of the following exception:

Traceback (most recent call last):
  File "/nas/ganluo/sglang/verify_queue_fix.py", line 172, in <module>
    asyncio.run(main(args))
  File "/usr/local/conda/envs/lg/lib/python3.10/asyncio/runners.py", line 44, in run
    return loop.run_until_complete(main)
  File "/usr/local/conda/envs/lg/lib/python3.10/asyncio/base_events.py", line 649, in run_until_complete
    return future.result()
  File "/nas/ganluo/sglang/verify_queue_fix.py", line 131, in main
    single_success = await test_single_request(args.base_url)
  File "/nas/ganluo/sglang/verify_queue_fix.py", line 37, in test_single_request
    result = await send_test_request(session, base_url)
  File "/nas/ganluo/sglang/verify_queue_fix.py", line 25, in send_test_request
    async with session.post(url + "/generate", json=payload) as response:
  File "/usr/local/conda/envs/lg/lib/python3.10/site-packages/aiohttp/client.py", line 1488, in __aenter__
    self._resp: _RetType = await self._coro
  File "/usr/local/conda/envs/lg/lib/python3.10/site-packages/aiohttp/client.py", line 770, in _request
    resp = await handler(req)
  File "/usr/local/conda/envs/lg/lib/python3.10/site-packages/aiohttp/client.py", line 725, in _connect_and_send_request
    conn = await self._connector.connect(
  File "/usr/local/conda/envs/lg/lib/python3.10/site-packages/aiohttp/connector.py", line 642, in connect
    proto = await self._create_connection(req, traces, timeout)
  File "/usr/local/conda/envs/lg/lib/python3.10/site-packages/aiohttp/connector.py", line 1209, in _create_connection
    _, proto = await self._create_direct_connection(req, traces, timeout)
  File "/usr/local/conda/envs/lg/lib/python3.10/site-packages/aiohttp/connector.py", line 1581, in _create_direct_connection
    raise last_exc
  File "/usr/local/conda/envs/lg/lib/python3.10/site-packages/aiohttp/connector.py", line 1550, in _create_direct_connection
    transp, proto = await self._wrap_create_connection(
  File "/usr/local/conda/envs/lg/lib/python3.10/site-packages/aiohttp/connector.py", line 1291, in _wrap_create_connection
    raise client_error(req.connection_key, exc) from exc
aiohttp.client_exceptions.ClientConnectorError: Cannot connect to host localhost:30000 ssl:default [Multiple exceptions: [Errno 111] Connect call failed ('::1', 30000, 0, 0), [Errno 111] Connect call failed ('127.0.0.1', 30000)]
